Workbook

Sheet TP_Ky_thuat
A1: CÔNG TY CỔ PHẦN ĐẦU TƯ CÔNG NGHỆ HOÀNG MINH (HMICO) | G1: CỘNG HÒA XÃ HỘI CHỦ NGHĨA VIỆT NAM
A2: BM.01-KPI.KYTHUAT | G2: Độc lập - Tự do - Hạnh phúc
A4: BIỂU MẪU ĐÁNH GIÁ KPI HOÀN THÀNH CÔNG VIỆC
A5: Tháng: 08/2026
A7: Họ và tên: | F7: Cấp bậc (Level):
A8: Mã nhân viên: | F8: Kỳ đánh giá (Tháng/Năm):
A9: Phòng/ Ban: | C9: Phòng Kỹ thuật | F9: Người đánh giá (Trưởng bộ phận):
A10: Chức danh: | C10: Kỹ sư triển khai | F10: Ngày đánh giá:
A12: MỤC 1. BSC CÔNG VIỆC (BALANCED SCORECARD) - Tổng trọng số: 70%
A13: STT | B13: Mục tiêu/ Tiêu chí đánh giá | C13: Chỉ tiêu cụ thể | D13: Trọng số (%) | E13: Thang điểm tối đa | F13: NGƯỜI LAO ĐỘNG TỰ ĐÁNH GIÁ | I13: TRƯỞNG BỘ PHẬN ĐÁNH GIÁ | L13: Ghi chú
F14: Điểm đạt được | G14: % đạt tiêu chí | H14: % đóng góp/tổng | I14: Điểm đạt được | J14: % đạt tiêu chí | K14: % đóng góp/tổng
A15: 1 | B15: Tiến độ hoàn thành Shop Drawing | C15: Hoàn thành bản vẽ đúng kế hoạch; đáp ứng tiến độ phát hành, trình duyệt và điều chỉnh theo yêu cầu dự án. Chủ động cảnh báo khi có nguy cơ chậm tiến độ. | D15: 0.15 | E15: 10 | F15: =Sheet1!G2 -> 10 | G15: =IFERROR(F15/E15,0) -> 1 | H15: =G15*D15 -> 0.15 | I15: =Sheet1!I2 -> 10 | J15: =IFERROR(I15/E15,0) -> 1 | K15: =J15*D15 -> 0.15
A16: 2 | B16: Độ chính xác của bản vẽ | C16: 90% bản vẽ thể hiện đúng thiết kế, BOQ, thông số thiết bị, kích thước, vị trí lắp đặt, kết nối và các yêu cầu kỹ thuật. Hạn chế sai sót phải sửa lại. | D16: 0.15 | E16: 10 | F16: =Sheet1!G10 -> 10 | G16: =IFERROR(F16/E16,0) -> 1 | H16: =G16*D16 -> 0.15 | I16: =Sheet1!I10 -> 10 | J16: =IFERROR(I16/E16,0) -> 1 | K16: =J16*D16 -> 0.15
A17: 3 | B17: Tính đầy đủ & đồng bộ của hồ sơ | C17: Đầy đủ các bản vẽ cần thiết: layout, detail, schematic, wiring/connection, mounting, rack layout... Các bản vẽ thống nhất thông tin, ký hiệu, mã thiết bị và revision. | D17: 0.1 | E17: 10 | F17: =Sheet1!G18 -> 10 | G17: =IFERROR(F17/E17,0) -> 1 | H17: =G17*D17 -> 0.1 | I17: =Sheet1!I18 -> 10 | J17: =IFERROR(I17/E17,0) -> 1 | K17: =J17*D17 -> 0.1
A18: 4 | B18: Tính khả thi thi công | C18: Bản vẽ phải thể hiện được phương án có thể triển khai thực tế: vị trí, kích thước, cao độ, tuyến cáp, giá đỡ, khoảng không gian lắp đặt, phương án đấu nối... Hạn chế tình trạng bản vẽ đúng trên giấy nhưng khó/không thể thi công. | D18: 0.1 | E18: 10 | F18: =Sheet1!G25 -> 10 | G18: =IFERROR(F18/E18,0) -> 1 | H18: =G18*D18 -> 0.1 | I18: =Sheet1!I25 -> 10 | J18: =IFERROR(I18/E18,0) -> 1 | K18: =J18*D18 -> 0.1
A19: 5 | B19: Phối hợp & xử lý yêu cầu kỹ thuật | C19: Phối hợp với Project Manager, kỹ thuật triển khai, tư vấn, khách hàng và các bộ môn liên quan; tiếp nhận và cập nhật comment; xử lý các vấn đề xung đột giữa bản vẽ và thực tế. | D19: 0.1 | E19: 10 | F19: =Sheet1!G34 -> 10 | G19: =IFERROR(F19/E19,0) -> 1 | H19: =G19*D19 -> 0.1 | I19: =Sheet1!I34 -> 10 | J19: =IFERROR(I19/E19,0) -> 1 | K19: =J19*D19 -> 0.1
A20: 6 | B20: Quản lý hồ sơ & kiểm soát Revision | C20: Đặt tên file, mã bản vẽ, revision, ngày phát hành, lưu trữ và cập nhật hồ sơ đúng quy định. Đảm bảo sử dụng đúng phiên bản mới nhất và không phát hành nhầm bản cũ. | D20: 0.1 | E20: 10 | F20: =Sheet1!G43 -> 10 | G20: =IFERROR(F20/E20,0) -> 1 | H20: =G20*D20 -> 0.1 | I20: =Sheet1!I43 -> 10 | J20: =IFERROR(I20/E20,0) -> 1 | K20: =J20*D20 -> 0.1
A21: Cộng Mục 1 (BSC công việc) | D21: =SUM(D15:D20) -> 0.7 | H21: =SUM(H15:H20) -> 0.7 | K21: =SUM(K15:K20) -> 0.7
A22: MỤC 2. CHẤP HÀNH NỘI QUY, QUY ĐỊNH CÔNG TY - Tổng trọng số: 30%
A23: 1 | B23: Số lần đi trễ/ về sớm không phép | C23: Số lần đi trễ/ về sớm trên 30 phút. | D23: 0.1 | E23: 3 | G23: =IFERROR(F23/E23,0) -> 0 | H23: =G23*D23 -> 0 | J23: =IFERROR(I23/E23,0) -> 0 | K23: =J23*D23 -> 0
A24: 2 | B24: Vi phạm bộ phận chưa xử lý kịp thời | D24: 0.1 | E24: 3 | G24: =IFERROR(F24/E24,0) -> 0 | H24: =G24*D24 -> 0 | J24: =IFERROR(I24/E24,0) -> 0 | K24: =J24*D24 -> 0
A25: 3 | B25: Giữ gìn văn hóa doanh nghiệp, chấp hành nội quy lao động. | D25: 0.1 | E25: 3 | G25: =IFERROR(F25/E25,0) -> 0 | H25: =G25*D25 -> 0 | J25: =IFERROR(I25/E25,0) -> 0 | K25: =J25*D25 -> 0
A26: Cộng Mục 2 (Chấp hành nội quy) | D26: =SUM(D23:D25) -> 0.3 | H26: =SUM(H23:H25) -> 0 | K26: =SUM(K23:K25) -> 0
A27: ="TỔNG ĐIỂM KPI HOÀN THÀNH CÔNG VIỆC (kiểm tra tổng trọng số = "&TEXT(D21+D26,"0%")&")" -> TỔNG ĐIỂM KPI HOÀN THÀNH CÔNG VIỆC (kiểm tra tổng trọng số = 100%) | F27: TỔNG (NLĐ tự ĐG): | H27: =H21+H26 -> 0.7 | I27: TỔNG (QL đánh giá): | K27: =K21+K26 -> 0.7
A28: XẾP LOẠI KẾT QUẢ ĐÁNH GIÁ | F28: =IF(K27>1,"VƯỢT CHỈ TIÊU",IF(K27>=0.9,"HOÀN THÀNH",IF(K27>=0.8,"CẦN CẢI THIỆN","CHƯA ĐẠT"))) -> CHƯA ĐẠT
A29: Thang xếp loại (4 bậc, theo Tổng điểm KPI - QL đánh giá): <80% Chưa đạt | 80-89% Cần cải thiện | 90-100% Hoàn thành | >100% Vượt chỉ tiêu (mức tham chiếu 100-120%)
A30: (*) Chưa đạt (<80%): Không hoàn thành nhiều chỉ tiêu quan trọng, cần xem xét lại thái độ và năng lực, có thể cân nhắc lại tính hiệu quả công việc.
A31: NGƯỜI LAO ĐỘNG | C31: TRƯỞNG BỘ PHẬN | E31: PHÒNG HCNS | J31: BAN GIÁM ĐỐC
A32: Ký ghi rõ họ tên | C32: Ký ghi rõ họ tên | E32: Ký ghi rõ họ tên | J32: Ký ghi rõ họ tên (Trường hợp phải soát xét)
A35: Gửi kết quả đánh giá về Phòng HCNS trước ngày 02 tháng kế tiếp.

Sheet Sheet1
F1: Kỹ thuật chấm | H1: Trưởng phòng chấm
B2: Tiến độ hoàn thành Shop Drawing | G2: =SUM(G4:G8) -> 10 | I2: =SUM(I4:I8) -> 10
B3: KPI | C3: Cách đo | D3: Mục tiêu | E3: Trọng số | F3: Điểm hoàn thành | G3: Điểm đạt được | H3: Điểm hoàn thành | I3: Điểm đạt được
B4: Hoàn thành bản vẽ theo kế hoạch được giao. | C4: Tỷ lệ bản vẽ hoàn thành đúng thời hạn = Số bản vẽ hoàn thành đúng hạn / Tổng số bản vẽ được giao × 100% | D4: ≥ 95% | E4: 0.2 | F4: 10 | G4: =E4*F4 -> 2 | H4: 10 | I4: =E4*H4 -> 2
B5: Đảm bảo thời gian phát hành bản vẽ phục vụ thi công/trình duyệt. | C5: Tỷ lệ bản vẽ hoàn thành đúng thời hạn = Số bản vẽ hoàn thành đúng hạn / Tổng số bản vẽ được giao × 100% | D5: ≥ 95% | E5: 0.2 | F5: 10 | G5: =E5*F5 -> 2 | H5: 10 | I5: =E5*H5 -> 2
B6: Chủ động cập nhật tiến độ và cảnh báo sớm khi có nguy cơ chậm. | C6: Tỷ lệ bản vẽ hoàn thành đúng thời hạn = Số bản vẽ hoàn thành đúng hạn / Tổng số bản vẽ được giao × 100% | D6: ≥ 95% | E6: 0.2 | F6: 10 | G6: =E6*F6 -> 2 | H6: 10 | I6: =E6*H6 -> 2
B7: Ưu tiên xử lý các bản vẽ ảnh hưởng trực tiếp đến tiến độ thi công. | C7: Tỷ lệ bản vẽ hoàn thành đúng thời hạn = Số bản vẽ hoàn thành đúng hạn / Tổng số bản vẽ được giao × 100% | D7: ≥ 95% | E7: 0.2 | F7: 10 | G7: =E7*F7 -> 2 | H7: 10 | I7: =E7*H7 -> 2
B8: Hoàn thành việc chỉnh sửa/re-submit theo thời hạn yêu cầu. | C8: Tỷ lệ bản vẽ hoàn thành đúng thời hạn = Số bản vẽ hoàn thành đúng hạn / Tổng số bản vẽ được giao × 100% | D8: ≥ 95% | E8: 0.2 | F8: 10 | G8: =E8*F8 -> 2 | H8: 10 | I8: =E8*H8 -> 2
B10: Độ chính xác của bản vẽ | G10: =SUM(G12:G16) -> 10 | I10: =SUM(I12:I16) -> 10
B11: KPI | C11: Cách đo | D11: Mục tiêu | E11: Trọng số | F11: Điểm hoàn thành | G11: Điểm đạt được | H11: Điểm hoàn thành | I11: Điểm đạt được
B12: Thể hiện đúng thiết kế, BOQ, thông số kỹ thuật và yêu cầu của dự án. | C12: Tỷ lệ bản vẽ đạt = Số bản vẽ không có lỗi nghiêm trọng / Tổng số bản vẽ được kiểm tra × 100%. | D12: ≥ 95% | E12: 0.25 | F12: 10 | G12: =E12*F12 -> 2.5 | H12: 10 | I12: =E12*H12 -> 2.5
B13: Chính xác về model, mã thiết bị, số lượng, kích thước, vị trí, cao độ và kết nối. | C13: Tỷ lệ bản vẽ đạt = Số bản vẽ không có lỗi nghiêm trọng / Tổng số bản vẽ được kiểm tra × 100%. | D13: ≥ 95% | E13: 0.25 | F13: 10 | G13: =E13*F13 -> 2.5 | H13: 10 | I13: =E13*H13 -> 2.5
B14: Các thông tin trên các bản vẽ phải thống nhất với nhau. | C14: Tỷ lệ bản vẽ đạt = Số bản vẽ không có lỗi nghiêm trọng / Tổng số bản vẽ được kiểm tra × 100%. | D14: ≥ 95% | E14: 0.15 | F14: 10 | G14: =E14*F14 -> 1.5 | H14: 10 | I14: =E14*H14 -> 1.5
B15: Hạn chế lỗi sai phải chỉnh sửa sau khi phát hành. | C15: Tỷ lệ bản vẽ đạt = Số bản vẽ không có lỗi nghiêm trọng / Tổng số bản vẽ được kiểm tra × 100%. | D15: ≥ 95% | E15: 0.25 | F15: 10 | G15: =E15*F15 -> 2.5 | H15: 10 | I15: =E15*H15 -> 2.5
B16: Không bỏ sót các thay đổi đã được phê duyệt. | C16: Tỷ lệ bản vẽ đạt = Số bản vẽ không có lỗi nghiêm trọng / Tổng số bản vẽ được kiểm tra × 100%. | D16: ≥ 95% | E16: 0.1 | F16: 10 | G16: =E16*F16 -> 1 | H16: 10 | I16: =E16*H16 -> 1
B18: Tính đầy đủ & đồng bộ của hồ sơ | G18: =SUM(G20:G23) -> 10 | I18: =SUM(I20:I23) -> 10
B19: KPI | C19: Cách đo | D19: Mục tiêu | E19: Trọng số | F19: Điểm hoàn thành | G19: Điểm đạt được | H19: Điểm hoàn thành | I19: Điểm đạt được
B20: Đầy đủ các bản vẽ theo SOW/yêu cầu dự án. | C20: Tỷ lệ hồ sơ đầy đủ = Số bộ hồ sơ đáp ứng đầy đủ yêu cầu / Tổng số bộ hồ sơ × 100%. Kiểm tra bằng checklist trước khi phát hành. | D20: ≥ 95% | E20: 0.25 | F20: 10 | G20: =E20*F20 -> 2.5 | H20: 10 | I20: =E20*H20 -> 2.5
B21: Bao gồm các bản vẽ cần thiết như Layout, Schematic, Wiring/Connection Diagram, Rack Layout, Detail, Mounting, Cable Routing... tùy phạm vi dự án. | C21: Tỷ lệ hồ sơ đầy đủ = Số bộ hồ sơ đáp ứng đầy đủ yêu cầu / Tổng số bộ hồ sơ × 100%. Kiểm tra bằng checklist trước khi phát hành. | D21: ≥ 95% | E21: 0.25 | F21: 10 | G21: =E21*F21 -> 2.5 | H21: 10 | I21: =E21*H21 -> 2.5
B22: Đồng bộ mã thiết bị, ký hiệu, legend, thông số và revision giữa các bản vẽ. | C22: Tỷ lệ hồ sơ đầy đủ = Số bộ hồ sơ đáp ứng đầy đủ yêu cầu / Tổng số bộ hồ sơ × 100%. Kiểm tra bằng checklist trước khi phát hành. | D22: ≥ 95% | E22: 0.25 | F22: 10 | G22: =E22*F22 -> 2.5 | H22: 10 | I22: =E22*H22 -> 2.5
B23: Thông tin trên Shop Drawing phù hợp với BOQ, thiết kế và hồ sơ liên quan. | C23: Tỷ lệ hồ sơ đầy đủ = Số bộ hồ sơ đáp ứng đầy đủ yêu cầu / Tổng số bộ hồ sơ × 100%. Kiểm tra bằng checklist trước khi phát hành. | D23: ≥ 95% | E23: 0.25 | F23: 10 | G23: =E23*F23 -> 2.5 | H23: 10 | I23: =E23*H23 -> 2.5
B25: Tính khả thi thi công | G25: =SUM(G27:G31) -> 10 | I25: =SUM(I27:I31) -> 10
B26: KPI | C26: Cách đo | D26: Mục tiêu | E26: Trọng số | F26: Điểm hoàn thành | G26: Điểm đạt được | H26: Điểm hoàn thành | I26: Điểm đạt được
B27: Bản vẽ phải phản ánh được phương án có thể triển khai thực tế | C27: Tỷ lệ bản vẽ không phát sinh lỗi thi công = Số bản vẽ không gây lỗi / Tổng số bản vẽ × 100%. | D27: ≥ 95% | E27: 0.2 | F27: 10 | G27: =E27*F27 -> 2 | H27: 10 | I27: =E27*H27 -> 2
B28: Kiểm tra không gian lắp đặt, kích thước, cao độ, vị trí thiết bị và khả năng tiếp cận bảo trì. | C28: Tỷ lệ bản vẽ không phát sinh lỗi thi công = Số bản vẽ không gây lỗi / Tổng số bản vẽ × 100%. | D28: ≥ 95% | E28: 0.2 | F28: 10 | G28: =E28*F28 -> 2 | H28: 10 | I28: =E28*H28 -> 2
B29: Thể hiện đầy đủ tuyến cáp, điểm đấu nối, giá đỡ, phụ kiện và phương án mounting khi cần. | C29: Tỷ lệ bản vẽ không phát sinh lỗi thi công = Số bản vẽ không gây lỗi / Tổng số bản vẽ × 100%. | D29: ≥ 95% | E29: 0.2 | F29: 10 | G29: =E29*F29 -> 2 | H29: 10 | I29: =E29*H29 -> 2
B30: Kiểm tra sự phù hợp với hiện trạng và phối hợp với các bộ môn khác. | C30: Tỷ lệ bản vẽ không phát sinh lỗi thi công = Số bản vẽ không gây lỗi / Tổng số bản vẽ × 100%. | D30: ≥ 95% | E30: 0.2 | F30: 10 | G30: =E30*F30 -> 2 | H30: 10 | I30: =E30*H30 -> 2
B31: Chủ động phát hiện các điểm bất khả thi hoặc xung đột trước khi đưa ra công trường. | C31: Tỷ lệ bản vẽ không phát sinh lỗi thi công = Số bản vẽ không gây lỗi / Tổng số bản vẽ × 100%. | D31: ≥ 95% | E31: 0.2 | F31: 10 | G31: =E31*F31 -> 2 | H31: 10 | I31: =E31*H31 -> 2
B34: Phối hợp & xử lý yêu cầu kỹ thuật | G34: =SUM(G36:G41) -> 10 | I34: =SUM(I36:I41) -> 10
B35: KPI | C35: Cách đo | D35: Mục tiêu | E35: Trọng số | F35: Điểm hoàn thành | G35: Điểm đạt được | H35: Điểm hoàn thành | I35: Điểm đạt được
B36: Phối hợp với PM, kỹ sư triển khai, giám sát, tư vấn, khách hàng và các bộ môn liên quan. | C36: Tỷ lệ yêu cầu xử lý đúng hạn = Số yêu cầu/comment xử lý đúng hạn / Tổng số yêu cầu × 100%. Theo dõi thêm số trường hợp chậm do không phản hồi hoặc không chủ động phối hợp. | D36: ≥ 90% | E36: 0.15 | F36: 10 | G36: =E36*F36 -> 1.5 | H36: 10 | I36: =E36*H36 -> 1.5
B37: Tiếp nhận và xử lý comment trên bản vẽ. | C37: Tỷ lệ yêu cầu xử lý đúng hạn = Số yêu cầu/comment xử lý đúng hạn / Tổng số yêu cầu × 100%. Theo dõi thêm số trường hợp chậm do không phản hồi hoặc không chủ động phối hợp. | D37: ≥ 90% | E37: 0.15 | F37: 10 | G37: =E37*F37 -> 1.5 | H37: 10 | I37: =E37*H37 -> 1.5
B38: Phản hồi các vấn đề kỹ thuật trong phạm vi công việc. | C38: Tỷ lệ yêu cầu xử lý đúng hạn = Số yêu cầu/comment xử lý đúng hạn / Tổng số yêu cầu × 100%. Theo dõi thêm số trường hợp chậm do không phản hồi hoặc không chủ động phối hợp. | D38: ≥ 90% | E38: 0.15 | F38: 10 | G38: =E38*F38 -> 1.5 | H38: 10 | I38: =E38*H38 -> 1.5
B39: Chủ động hỏi/xác nhận khi thông tin đầu vào chưa đầy đủ. | C39: Tỷ lệ yêu cầu xử lý đúng hạn = Số yêu cầu/comment xử lý đúng hạn / Tổng số yêu cầu × 100%. Theo dõi thêm số trường hợp chậm do không phản hồi hoặc không chủ động phối hợp. | D39: ≥ 90% | E39: 0.2 | F39: 10 | G39: =E39*F39 -> 2 | H39: 10 | I39: =E39*H39 -> 2
B40: Phát hiện và đề xuất giải pháp đối với các điểm xung đột giữa thiết kế và thực tế. | C40: Tỷ lệ yêu cầu xử lý đúng hạn = Số yêu cầu/comment xử lý đúng hạn / Tổng số yêu cầu × 100%. Theo dõi thêm số trường hợp chậm do không phản hồi hoặc không chủ động phối hợp. | D40: ≥ 90% | E40: 0.2 | F40: 10 | G40: =E40*F40 -> 2 | H40: 10 | I40: =E40*H40 -> 2
B41: Theo dõi đến khi các comment/yêu cầu được đóng. | C41: Tỷ lệ yêu cầu xử lý đúng hạn = Số yêu cầu/comment xử lý đúng hạn / Tổng số yêu cầu × 100%. Theo dõi thêm số trường hợp chậm do không phản hồi hoặc không chủ động phối hợp. | D41: ≥ 90% | E41: 0.15 | F41: 10 | G41: =E41*F41 -> 1.5 | H41: 10 | I41: =E41*H41 -> 1.5
B43: Quản lý hồ sơ & kiểm soát Revision | G43: =SUM(G45:G50) -> 10 | I43: =SUM(I45:I50) -> 10
B44: KPI | C44: Cách đo | D44: Mục tiêu | E44: Trọng số | F44: Điểm hoàn thành | G44: Điểm đạt được | H44: Điểm hoàn thành | I44: Điểm đạt được
B45: Tuân thủ quy định đặt tên, mã số và cấu trúc hồ sơ. | C45: Tỷ lệ hồ sơ quản lý đúng quy định = Hồ sơ đạt yêu cầu / Tổng hồ sơ kiểm tra × 100%. Theo dõi số lỗi liên quan đến tên file, revision, phát hành nhầm bản vẽ hoặc thiếu file nguồn. | D45: ≥ 90% | E45: 0.25 | F45: 10 | G45: =E45*F45 -> 2.5 | H45: 10 | I45: =E45*H45 -> 2.5
B46: Quản lý đúng revision, ngày phát hành và lịch sử thay đổi. | C46: Tỷ lệ hồ sơ quản lý đúng quy định = Hồ sơ đạt yêu cầu / Tổng hồ sơ kiểm tra × 100%. Theo dõi số lỗi liên quan đến tên file, revision, phát hành nhầm bản vẽ hoặc thiếu file nguồn. | D46: ≥ 90% | E46: 0.15 | F46: 10 | G46: =E46*F46 -> 1.5 | H46: 10 | I46: =E46*H46 -> 1.5
...
